import pytest
import requests
from coinmetrics._exceptions import (
    CoinMetricsClientQueryParamsException,
)
from coinmetrics.api_client import CoinMetricsClient
import os

client = CoinMetricsClient(str(os.environ.get("CM_API_KEY")))
cm_api_key_set = os.environ.get("CM_API_KEY") is not None
REASON_TO_SKIP = "Need to set CM_API_KEY as an env var in order to run this test"

print("CM_API_KEY is set - tests will run") if cm_api_key_set else print(
    "CM_API_KEY not set, tests will not run"
)


@pytest.mark.skipif(not cm_api_key_set, reason=REASON_TO_SKIP)
def test_custom_414_error() -> None:
    """
    Test for CoinMetricsClientQueryParamsException hitting a 414 error.
    """
    markets = [market["market"] for market in client.reference_data_markets()]
    try:
        intentional_414 = client.reference_data_markets(markets=markets)
    except Exception as e:
        assert type(e) == CoinMetricsClientQueryParamsException
        print(e)


@pytest.mark.skipif(not cm_api_key_set, reason=REASON_TO_SKIP)
def test_custom_exception_not_raised_for_403() -> None:
    """
    Tests that custom exceptions are not raised for unauthorized - just a normal HTTPError, If a different error is
    is raised it asserts false
    """
    unauthorized_client = CoinMetricsClient(api_key="Invalid API Key")
    try:
        intentional_401 = unauthorized_client.reference_data_markets()
    except requests.HTTPError as e:
        assert e.response is not None
        assert e.response.status_code == 401
    except Exception as e:
        assert False

if __name__ == "__main__":
    pytest.main()
